Workbook

Sheet Dashboard
B2: HEXALEVEL — MONTHLY REVENUE DASHBOARD
B3: All values update automatically — add rows to Projects / Revenue Split / Expenses
B5: TOTAL REVENUE (PKR) | F5: COMPANY SHARE (50%) | J5: TEAM SHARE (50%) | N5: TOTAL PURCHASES
B6: ='Revenue Split'!B24 -> 676771 | F6: ='Revenue Split'!C24 -> 338385 | J6: ='Revenue Split'!D24 -> 338385 | N6: =Expenses!C10 -> 14247.22
B8: NET PROFIT | F8: TOTAL PROJECTS | J8: PAYMENTS RECEIVED | N8: SEND MONEY TOTAL
B9: ='Revenue Split'!C24-Expenses!C10-'Send Money'!B12 -> 309687.78 | F9: =COUNTA(Projects!B3:B59) -> 23 | J9: =COUNTIF(Projects!G3:G59,"Received")+COUNTIF(Projects!G3:G59,"Recived")+COUNTIF(Projects!G3:G59,"Received ") -> 22 | N9: ='Send Money'!B12 -> 14450
B11: NEW SPLIT — FROM 1 SEP 2026 (Company 30% · Shaista / Amara / Urooj 23.33% each)
B13: TOTAL REVENUE (PKR) | F13: COMPANY SHARE (Total) | J13: TEAM SHARE (Total) | N13: TOTAL PURCHASES
B14: ='Revenue Split'!B48 -> 20000 | F14: ='Revenue Split'!C48 -> 6000 | J14: ='Revenue Split'!D48+'Revenue Split'!E48+'Revenue Split'!F48 -> 14000 | N14: =Expenses!C29 -> 0
B16: NET PROFIT | F16: TOTAL PROJECTS | J16: PAYMENTS RECEIVED | N16: SEND MONEY TOTAL
B17: ='Revenue Split'!C48-Expenses!C29-'Send Money'!B31 -> 6000 | F17: =COUNTA('Revenue Split'!A28:A47) -> 1 | J17: =COUNTIF('Revenue Split'!G28:G47,"Received")+COUNTIF('Revenue Split'!G28:G47,"Recived")+COUNTIF('Revenue Split'!G28:G47,"Received ") -> 1 | N17: ='Send Money'!B31 -> 0
B19: OVERALL SUMMARY (Old + New Combined)
B21: OVERALL REVENUE (PKR) | F21: OVERALL NET PROFIT | J21: TOTAL PROJECTS | N21: PAYMENTS RECEIVED
B22: ='Revenue Split'!B24+'Revenue Split'!B48 -> 696771 | F22: ='Revenue Split'!C24+'Revenue Split'!C48-Expenses!C10-'Send Money'!B12-Expenses!C29-'Send Money'!B31 -> 315687.78 | J22: =COUNTA(Projects!B3:B59) -> 23 | N22: =COUNTIF(Projects!G3:G59,"Received")+COUNTIF(Projects!G3:G59,"Recived")+COUNTIF(Projects!G3:G59,"Received ") -> 22

Sheet Projects
A1: HEXALEVEL — CLIENT PROJECTS TRACKER
A2: Project Start | B2: Client Name | C2: Project Name | D2: Service Type | E2: Amount | F2: Currency | G2: Payment Status | H2: Payment Date | I2: Notes | J2: Bank
A3: Dec 2025 | B3: Ranked Skill | C3: Mortgage Leads flow | D3: CRM | E3: 25000 | F3: PKR | G3: Received | H3: 12-Jan-2026 | I3: Received | J3: Meezan
A4: Jan 2026 | B4: India | C4: Crm +Wp | D4: Both | E4: 15000 | F4: INR | G4: Received | H4: 20-Feb-2026 | I4: Received | J4: Payoneer
A5: 46023 | B5: USA | C5: GHL all services | D5: CRM | E5: 350 | F5: USD | G5: Pending | I5: Waiting for payment
A6: 46023 | B6: Lahore | C6: Life insurance | D6: CRM | E6: 40000 | F6: PKR | G6: Received | H6: 21-Feb-2026 | I6: Received | J6: HBL
A7: Jan 2026 | B7: Mehroz | C7: GHL Work | D7: CRM | E7: 28600 | F7: PKR | G7: Received | H7: 3 Mar 2026 | I7: Received | J7: Meezan
A8: Dec 2025 | B8: Waleed | C8: Seo site | D8: WP | E8: 29000 | F8: PKR | G8: Received | H8: 25 Feb 2026 | I8: Received | J8: Nayapay
A9: Mar 2026 | B9: Upwork | C9: Funnel designing | D9: CRM | E9: 9382 | F9: PKR | G9: Received | H9: 15 Mar 2026 | I9: Received | J9: Meezan
A10: Mar 2026 | B10: India | C10: Crm +Wp | D10: Both | E10: 15000 | F10: INR | G10: Received | H10: 20-Feb-2026 | I10: Received | J10: Payoneer
A11: Mar 2026 | B11: Mehroz | C11: A2p | D11: CRM | E11: 19250 | F11: PKR | G11: Received | H11: 27 Mar 2026 | I11: Received | J11: Meezan
A12: 46113 | B12: haris | C12: GHL | D12: CRM | E12: 46334 | F12: PKR | G12: Received | H12: 46118 | I12: Received | J12: Payoneer
A13: 46113 | B13: Mehroz | C13: A2p | D13: CRM | E13: 33600 | F13: PKR | G13: Received | H13: 46128 | I13: Received | J13: Meezan
A14: 46113 | B14: India | C14: CRM+WP | D14: Both | E14: 42199 | F14: PKR | G14: Received | H14: 46136 | I14: Received | J14: Payoneer
A15: 46113 | B15: Usa + Fiver | C15: GHL | D15: CRM | E15: 80163 | F15: PKR | G15: Received | H15: 46137 | I15: Received | J15: HBL
A16: 46143 | B16: Haris | C16: GHL | D16: CRM | E16: 44401 | F16: PKR | G16: Received | H16: 46145 | I16: Received | J16: Payoneer
A17: 46143 | B17: Usa | C17: GHL | D17: CRM | E17: 85616 | F17: PKR | G17: Received | H17: 46157 | I17: Received | J17: Askari
A18: 46143 | B18: Mehroz | C18: A2P | D18: CRM | E18: 29400 | F18: PKR | G18: Received | H18: 46160 | I18: Received | J18: Askari
A19: 46174 | B19: Haris | C19: GHL | D19: CRM | E19: 44614 | F19: PKR | G19: Received | H19: 46177 | I19: Received | J19: Payoneer
A20: 46193 | B20: shelim | C20: WP | D20: WP | E20: 7000 | F20: PKR | G20: Received | H20: 46193 | I20: Received | J20: Askari
A21: 46215 | B21: Sheen | C21: GHL | D21: CRM | E21: 15000 | F21: PKR | G21: Received | H21: 46215 | I21: Received | J21: Meezan
A22: 46277 | B22: Usa | C22: GHL | D22: CRM | E22: 23113 | F22: PKR | G22: Received | H22: 46277 | I22: Received | J22: Askari
A23: 46295 | B23: USA | C23: GHL | D23: CRM | E23: 21920 | F23: PKR | G23: Received | H23: 46295 | I23: Received | J23: Askari
A24: 46322 | B24: USA | C24: GHL | D24: CRM | E24: 36099 | F24: PKR | G24: Received | H24: 46322 | I24: Received | J24: Askari
A25: TOTAL | E25: =SUMPRODUCT((ISNUMBER(E3:E11))*E3:E11) -> 181582
A26: 46314 | B26: Umair | C26: GHL | D26: CRM | E26: 20000 | F26: PKR | G26: Received | H26: 46314 | I26: Received | J26: Meezan

Sheet Revenue Split
A1: HEXALEVEL — REVENUE SPLIT | 50% Company · 50% Team
A2: Month | B2: Amount (PKR) | C2: Company 50% | D2: Team 50% | E2: Status | F2: Date Received | G2: Shaista | H2: Amara | I2: Tax on Transfer
A3: DEC | B3: 25000 | C3: =B3*0.5 -> 12500 | D3: =B3*0.5 -> 12500 | E3: Received | F3: 26 Jan 2026 | G3: Nayapay | H3: Askari
A4: FEB | B4: 54541 | C4: =B4*0.5 -> 27270.5 | D4: =B4*0.5 -> 27270.5 | E4: Received | F4: 20 Feb 2026 | G4: Nayapay | H4: Askari
A5: FEB | B5: 40000 | C5: =B5*0.5 -> 20000 | D5: =B5*0.5 -> 20000 | E5: Received | F5: 21 Feb 2026 | G5: HBI | H5: Askari
A6: FEB | B6: 29000 | C6: =B6*0.5 -> 14500 | D6: =B6*0.5 -> 14500 | E6: Received | F6: 25 Feb 2026 | G6: Nayapay | H6: Askari
A7: March | B7: 28600 | C7: =B7*0.5 -> 14300 | D7: =B7*0.5 -> 14300 | E7: Received | F7: 3 Mar 2026 | G7: Nayapay | H7: Nayapay
A8: March | B8: 9382 | C8: =B8*0.5 -> 4691 | D8: =B8*0.5 -> 4691 | E8: Received | F8: 15 Mar 2026 | G8: Nayapay | H8: Nayapay
A9: March | B9: 42671 | C9: =B9*0.5 -> 21335.5 | D9: =B9*0.5 -> 21335.5 | E9: Received | F9: 25 Mar 2026 | G9: Nayapay | H9: Nayapay
A10: March | B10: 19250 | C10: =B10*0.5 -> 9625 | D10: =B10*0.5 -> 9625 | E10: Received | F10: 27 Mar 2026 | G10: Nayapay | H10: Nayapay
A11: April | B11: 46334 | C11: =B11*0.5 -> 23167 | D11: =B11*0.5 -> 23167 | E11: Received | F11: 46118 | G11: Nayapay | H11: Askari
A12: April | B12: 33600 | C12: =B12*0.5 -> 16800 | D12: =B12*0.5 -> 16800 | E12: Received | F12: 46128 | G12: Nayapay | H12: Askari
A13: April | B13: 42199 | C13: =B13*0.5 -> 21099.5 | D13: =B13*0.5 -> 21099.5 | E13: Received | F13: 46136 | G13: Nayapay | H13: Askari
A14: April | B14: 80163 | C14: =B14*0.5 -> 40081.5 | D14: =B14*0.5 -> 40081.5 | E14: Received | F14: 46137 | G14: Hbl | H14: Askari
A15: May | B15: 44401 | C15: 22200 | D15: 22200 | E15: Received | F15: 46146 | G15: Nayapay | H15: Askari
A16: May | B16: 85616 | C16: 42808 | D16: 42808 | E16: Received | F16: 46157 | G16: Nayapay | H16: Askari
A17: May | B17: 29400 | C17: 14700 | D17: 14700 | E17: Received | F17: 46160 | G17: Nayapay | H17: Askari
A18: June | B18: 44614 | C18: 22307 | D18: 22307 | E18: Received | F18: 46177 | G18: Nayapay | H18: Askari
A19: June | B19: 7000 | C19: 3500 | D19: 3500 | E19: Received | F19: 46193 | G19: Nayapay | H19: Askari
A20: July | B20: 15000 | C20: 7500 | D20: 7500 | E20: Received | F20: 46215 | G20: Cutting | H20: Askari
A21: Sep | B21: 23113 | C21: 11556 | D21: 11556 | E21: Received | F21: 46277 | G21: Cutting | H21: Askari
A22: Sep | B22: 21920 | C22: 10960 | D22: 10960 | E22: Received | F22: 46295 | G22: Cutting | H22: Askari
A23: Sep | B23: 36099 | C23: 18049 | D23: 18049 | E23: Received | F23: 46322 | G23: Cutting | H23: Askari
A24: TOTAL | B24: =SUM(B3:B20) -> 676771 | C24: =SUM(C3:C20) -> 338385 | D24: =SUM(D3:D20) -> 338385
A26: HEXALEVEL — REVENUE SPLIT (NEW MODEL, effective 1 Sep 2026) | Company 30% · Shaista 23.33% · Amara 23.33% · Urooj 23.33%
A27: Month | B27: Amount (PKR) | C27: Company 30% | D27: Shaista 23.33% | E27: Amara 23.33% | F27: Urooj 23.33% | G27: Status | H27: Date Received | I27: Shaista | J27: Amara | K27: Urooj | L27: Tax on Transfer | M27: Notes
A28: Oct | B28: 20000 | C28: =IF(B28="","",B28*0.3) -> 6000 | D28: =IF(B28="","",B28*(0.7/3)) -> 4666.6667 | E28: =IF(B28="","",B28*(0.7/3)) -> 4666.6667 | F28: =IF(B28="","",B28*(0.7/3)) -> 4666.6667 | G28: Received | H28: 46314 | I28: Cutting | J28: Nayapay | K28: UBL
C29: =IF(B29="","",B29*0.3) | D29: =IF(B29="","",B29*(0.7/3)) | E29: =IF(B29="","",B29*(0.7/3)) | F29: =IF(B29="","",B29*(0.7/3))
C30: =IF(B30="","",B30*0.3) | D30: =IF(B30="","",B30*(0.7/3)) | E30: =IF(B30="","",B30*(0.7/3)) | F30: =IF(B30="","",B30*(0.7/3))
C31: =IF(B31="","",B31*0.3) | D31: =IF(B31="","",B31*(0.7/3)) | E31: =IF(B31="","",B31*(0.7/3)) | F31: =IF(B31="","",B31*(0.7/3))
C32: =IF(B32="","",B32*0.3) | D32: =IF(B32="","",B32*(0.7/3)) | E32: =IF(B32="","",B32*(0.7/3)) | F32: =IF(B32="","",B32*(0.7/3))
C33: =IF(B33="","",B33*0.3) | D33: =IF(B33="","",B33*(0.7/3)) | E33: =IF(B33="","",B33*(0.7/3)) | F33: =IF(B33="","",B33*(0.7/3))
C34: =IF(B34="","",B34*0.3) | D34: =IF(B34="","",B34*(0.7/3)) | E34: =IF(B34="","",B34*(0.7/3)) | F34: =IF(B34="","",B34*(0.7/3))
C35: =IF(B35="","",B35*0.3) | D35: =IF(B35="","",B35*(0.7/3)) | E35: =IF(B35="","",B35*(0.7/3)) | F35: =IF(B35="","",B35*(0.7/3))
C36: =IF(B36="","",B36*0.3) | D36: =IF(B36="","",B36*(0.7/3)) | E36: =IF(B36="","",B36*(0.7/3)) | F36: =IF(B36="","",B36*(0.7/3))
C37: =IF(B37="","",B37*0.3) | D37: =IF(B37="","",B37*(0.7/3)) | E37: =IF(B37="","",B37*(0.7/3)) | F37: =IF(B37="","",B37*(0.7/3))
C38: =IF(B38="","",B38*0.3) | D38: =IF(B38="","",B38*(0.7/3)) | E38: =IF(B38="","",B38*(0.7/3)) | F38: =IF(B38="","",B38*(0.7/3))
C39: =IF(B39="","",B39*0.3) | D39: =IF(B39="","",B39*(0.7/3)) | E39: =IF(B39="","",B39*(0.7/3)) | F39: =IF(B39="","",B39*(0.7/3))
C40: =IF(B40="","",B40*0.3) | D40: =IF(B40="","",B40*(0.7/3)) | E40: =IF(B40="","",B40*(0.7/3)) | F40: =IF(B40="","",B40*(0.7/3))
... C47: =IF(B47="","",B47*0.3) | D47: =IF(B47="","",B47*(0.7/3)) | E47: =IF(B47="","",B47*(0.7/3)) | F47: =IF(B47="","",B47*(0.7/3))
...

Sheet Expenses
A1: PURCHASES — Items & Prices
A2: Item / Purchase | B2: Name / Link | C2: Price (PKR)
A3: Domain | B3: theghlvideo.com | C3: 3314.4
A4: Upwork Connects | B4: $15 | C4: 4830
A5: Fiver Course | B5: Chain solution | C5: 1999
A6: 6 course Leads generation | B6: 6/6 course | C6: 1200
A7: Buy Crm | B7: Guarantee Crm | C7: 370
A8: BUY EMAIL THEGHLVIDEO | C8: 2533.82
A9: Renew hexalevel Domain | C9: 4955
A10: TOTAL | C10: =SUMIF(A3:A8,"<>TOTAL",C3:C8) -> 14247.22
A12: NEW PURCHASES — Items & Prices (from 1 Sep 2026, split 3 ways)
A13: Item / Purchase | B13: Name / Link | C13: Price (PKR)
A29: TOTAL | C29: =SUMIF(A14:A28,"<>TOTAL",C14:C28) -> 0

Sheet Send Money
A1: SEND MONEY — Payments Made
A2: Send Money To | B2: Amount Sent (PKR)
A3: Send Sundas for email testing | B3: 1200
A4: Meeting Fiver with Ahsan | B4: 10000
A5: Waqar Udhar | B5: 3250
C6: 5000
A12: TOTAL | B12: =SUMIF(A3:A11,"<>TOTAL",B3:B11) -> 14450
A14: NEW SEND MONEY — Payments Made (from 1 Sep 2026, split 3 ways)
A15: Send Money To | B15: Amount Sent (PKR)
A31: TOTAL | B31: =SUMIF(A16:A30,"<>TOTAL",B16:B30) -> 0
